Workbook

Sheet Cover Sheet

Sheet Sheet1
A1: All Dwellings | E1: All Dwellings
A2: Area/Ring/SA | B2: Greater Sydney | C2: Ku-ring-gai | D2: Manly | E2: Area/Ring/SA | F2: Greater Sydney | G2: Ku-ring-gai | H2: Manly | K2: Greater Sydney | L2: Ku-ring-gai | Q2: Greater Sydney | R2: Ku-ring-gai | S2: Manly
A3: Mar-91 | B3: 150 | C3: - | D3: 188 | E3: Mar-91
D4: s
A5: Jun-91 | B5: 155 | C5: - | D5: 210 | E5: Jun-91
A7: Sep-91 | B7: 158 | C7: 409 | D7: 280 | E7: Sep-91 | F7: =B7*Sheet4!$B$28/Sheet4!$B$2 -> 333.12587 | G7: =C7*Sheet4!$B$28/Sheet4!$B$2 -> 862.33217 | H7: =D7*Sheet4!$B$28/Sheet4!$B$2 -> 590.34965 | I7: Greater Sydney | J7: Ku-ring-gai | K7: 100 | L7: 100 | P7: 1991 | Q7: =AVERAGE(F7:F9) -> 340.50524 | R7: =AVERAGE(G7:G9) -> 800.13462 | S7: =AVERAGE(H7:H9) -> 521.82692
A9: Dec-91 | B9: 165 | C9: 350 | D9: 215 | E9: Dec-91 | F9: =B9*Sheet4!$B$28/Sheet4!$B$2 -> 347.88462 | G9: =C9*Sheet4!$B$28/Sheet4!$B$2 -> 737.93706 | H9: =D9*Sheet4!$B$28/Sheet4!$B$2 -> 453.3042 | I9: =(F9-F7)/F7 -> 0.044303797 | J9: =(G9-G7)/G7 -> -0.14425428 | K9: =F9/$F$7*100 -> 104.43038 | L9: =G9/$F$7*100 -> 221.51899 | P9: 1992 | Q9: =AVERAGE(F9:F11) -> 352.60897 | R9: =AVERAGE(G11:G17) -> 796.18333 | S9: =AVERAGE(H11:H17) -> 532.65 | T9: =(Q9-Q7)/Q7 -> 0.035546382 | U9: =(R9-R7)/R7 -> -0.0049382716 | V9: =(S9-S7)/S7 -> 0.020740741
A11: Mar-92 | B11: 160 | C11: 365 | D11: 228 | E11: Mar-92 | F11: =B11*Sheet4!$B$28/Sheet4!$B$3 -> 357.33333 | G11: =C11*Sheet4!$B$28/Sheet4!$B$3 -> 815.16667 | H11: =D11*Sheet4!$B$28/Sheet4!$B$3 -> 509.2 | I11: =(F11-F9)/F9 -> 0.027160494 | J11: =(G11-G9)/G9 -> 0.10465608 | K11: =F11/$F$7*100 -> 107.26676 | L11: =G11/$F$7*100 -> 244.7023 | P11: 1993 | Q11: =AVERAGE(F11:F13) -> 362.91667 | R11: =AVERAGE(G19:G25) -> 847.23184 | S11: =AVERAGE(H19:H25) -> 554.15363 | T11: =(Q11-Q9)/Q9 -> 0.029232643 | U11: =(R11-R9)/R9 -> 0.064116527 | V11: =(S11-S9)/S9 -> 0.040371034
A13: Jun-92 | B13: 165 | C13: 340 | D13: 235 | E13: Jun-92 | F13: =B13*Sheet4!$B$28/Sheet4!$B$3 -> 368.5 | G13: =C13*Sheet4!$B$28/Sheet4!$B$3 -> 759.33333 | H13: =D13*Sheet4!$B$28/Sheet4!$B$3 -> 524.83333 | I13: =(F13-F11)/F11 -> 0.03125 | J13: =(G13-G11)/G11 -> -0.068493151 | K13: =F13/$F$7*100 -> 110.61885 | L13: =G13/$F$7*100 -> 227.94187 | P13: 1994 | Q13: =AVERAGE(F13:F15) -> 368.5 | R13: =AVERAGE(G27:G33) -> 897.17383 | S13: =AVERAGE(H27:H33) -> 689.78692 | T13: =(Q13-Q11)/Q11 -> 0.015384615 | U13: =(R13-R11)/R11 -> 0.058947251 | V13: =(S13-S11)/S11 -> 0.24475755
A15: Sep-92 | B15: 165 | C15: 370 | D15: 245 | E15: Sep-92 | F15: =B15*Sheet4!$B$28/Sheet4!$B$3 -> 368.5 | G15: =C15*Sheet4!$B$28/Sheet4!$B$3 -> 826.33333 | H15: =D15*Sheet4!$B$28/Sheet4!$B$3 -> 547.16667 | I15: =(F15-F13)/F13 -> 0 | J15: =(G15-G13)/G13 -> 0.088235294 | K15: =F15/$F$7*100 -> 110.61885 | L15: =G15/$F$7*100 -> 248.05438 | P15: 1995 | Q15: =AVERAGE(F15:F17) -> 370.73333 | R15: =AVERAGE(G35:G41) -> 829.50504 | S15: =AVERAGE(H35:H41) -> 616.17479 | T15: =(Q15-Q13)/Q13 -> 0.0060606061 | U15: =(R15-R13)/R13 -> -0.075424391 | V15: =(S15-S13)/S13 -> -0.1067172
A17: Dec-92 | B17: 167 | C17: 351 | D17: 246 | E17: Dec-92 | F17: =B17*Sheet4!$B$28/Sheet4!$B$3 -> 372.96667 | G17: =C17*Sheet4!$B$28/Sheet4!$B$3 -> 783.9 | H17: =D17*Sheet4!$B$28/Sheet4!$B$3 -> 549.4 | I17: =(F17-F15)/F15 -> 0.012121212 | J17: =(G17-G15)/G15 -> -0.051351351 | K17: =F17/$F$7*100 -> 111.95968 | L17: =G17/$F$7*100 -> 235.31646 | P17: 1996 | Q17: =AVERAGE(F17:F19) -> 371.76266 | R17: =AVERAGE(G43:G49) -> 802.85423 | S17: =AVERAGE(H43:H49) -> 644.24756 | T17: =(Q17-Q15)/Q15 -> 0.002776469 | U17: =(R17-R15)/R15 -> -0.032128566 | V17: =(S17-S15)/S15 -> 0.045559746
A19: Mar-93 | B19: 165 | C19: 383 | D19: 240 | E19: Mar-93 | F19: =B19*Sheet4!$B$28/Sheet4!$B$4 -> 370.55866 | G19: =C19*Sheet4!$B$28/Sheet4!$B$4 -> 860.14525 | H19: =D19*Sheet4!$B$28/Sheet4!$B$4 -> 538.99441 | I19: =(F19-F17)/F17 -> -0.006456361 | J19: =(G19-G17)/G17 -> 0.097264002 | K19: =F19/$F$7*100 -> 111.23683 | L19: =G19/$F$7*100 -> 258.20428 | P19: 1997 | Q19: =AVERAGE(F19:F21) -> 376.17318 | R19: =AVERAGE(G51:G57) -> 978.28257 | S19: =AVERAGE(H51:H57) -> 790.90669 | T19: =(Q19-Q17)/Q17 -> 0.01186381 | U19: =(R19-R17)/R17 -> 0.21850584 | V19: =(S19-S17)/S17 -> 0.22764407
A20: s | E20: s
A21: Jun-93 | B21: 170 | C21: 390 | D21: 261 | E21: Jun-93 | F21: =B21*Sheet4!$B$28/Sheet4!$B$4 -> 381.78771 | G21: =C21*Sheet4!$B$28/Sheet4!$B$4 -> 875.86592 | H21: =D21*Sheet4!$B$28/Sheet4!$B$4 -> 586.15642 | I21: =(F21-F19)/F19 -> 0.03030303 | J21: =(G21-G19)/G19 -> 0.018276762 | K21: =F21/$F$7*100 -> 114.60764 | L21: =G21/$F$7*100 -> 262.92341 | P21: 1998 | Q21: =AVERAGE(F21:F23) -> 381.78771 | R21: =AVERAGE(G59:G65) -> 1058.4461 | S21: =AVERAGE(H59:H65) -> 924.20936 | T21: =(Q21-Q19)/Q19 -> 0.014925373 | U21: =(R21-R19)/R19 -> 0.081943137 | V21: =(S21-S19)/S19 -> 0.16854412
A22: s | E22: s
A23: Sep-93 | B23: 170 | C23: 353 | D23: 234 | E23: Sep-93 | F23: =B23*Sheet4!$B$28/Sheet4!$B$4 -> 381.78771 | G23: =C23*Sheet4!$B$28/Sheet4!$B$4 -> 792.77095 | H23: =D23*Sheet4!$B$28/Sheet4!$B$4 -> 525.51955 | I23: =(F23-F21)/F21 -> 0 | J23: =(G23-G21)/G21 -> -0.094871795 | K23: =F23/$F$7*100 -> 114.60764 | L23: =G23/$F$7*100 -> 237.9794 | P23: 1999 | Q23: =AVERAGE(F23:F25) -> 381.78771 | R23: =AVERAGE(G67:G73) -> 1138.6546 | S23: =AVERAGE(H67:H73) -> 988.42268 | T23: =(Q23-Q21)/Q21 -> 0 | U23: =(R23-R21)/R21 -> 0.075779508 | V23: =(S23-S21)/S21 -> 0.069479188
A24: s | E24: s
A25: Dec-93 | B25: 170 | C25: 383 | D25: 252 | E25: Dec-93 | F25: =B25*Sheet4!$B$28/Sheet4!$B$4 -> 381.78771 | G25: =C25*Sheet4!$B$28/Sheet4!$B$4 -> 860.14525 | H25: =D25*Sheet4!$B$28/Sheet4!$B$4 -> 565.94413 | I25: =(F25-F23)/F23 -> 0 | J25: =(G25-G23)/G23 -> 0.084985836 | K25: =F25/$F$7*100 -> 114.60764 | L25: =G25/$F$7*100 -> 258.20428 | P25: 2000 | Q25: =AVERAGE(F25:F27) -> 388.13685 | R25: =AVERAGE(G75:G81) -> 1159.1985 | S25: =AVERAGE(H75:H81) -> 1081.3603 | T25: =(Q25-Q23)/Q23 -> 0.016630016 | U25: =(R25-R23)/R23 -> 0.018042249 | V25: =(S25-S23)/S23 -> 0.094026185
A26: s | E26: s
A27: Mar-94 | B27: 175 | C27: 384 | D27: 282 | E27: Mar-94 | F27: =B27*Sheet4!$B$28/Sheet4!$B$5 -> 394.48598 | G27: =C27*Sheet4!$B$28/Sheet4!$B$5 -> 865.61495 | H27: =D27*Sheet4!$B$28/Sheet4!$B$5 -> 635.68598 | I27: =(F27-F25)/F25 -> 0.033260033 | J27: =(G27-G25)/G25 -> 0.0063590444 | K27: =F27/$F$7*100 -> 118.4195 | L27: =G27/$F$7*100 -> 259.84621 | P27: 2001 | Q27: =AVERAGE(F27:F29) -> 394.48598 | R27: =AVERAGE(G83:G89) -> 1219.8303 | S27: =AVERAGE(H83:H89) -> 1095.3578 | T27: =(Q27-Q25)/Q25 -> 0.016357983 | U27: =(R27-R25)/R25 -> 0.052304885 | V27: =(S27-S25)/S25 -> 0.012944348
A28: s | E28: s
A29: Jun-94 | B29: 175 | C29: 401 | D29: 310 | E29: Jun-94 | F29: =B29*Sheet4!$B$28/Sheet4!$B$5 -> 394.48598 | G29: =C29*Sheet4!$B$28/Sheet4!$B$5 -> 903.93645 | H29: =D29*Sheet4!$B$28/Sheet4!$B$5 -> 698.80374 | I29: =(F29-F27)/F27 -> 0 | J29: =(G29-G27)/G27 -> 0.044270833 | K29: =F29/$F$7*100 -> 118.4195 | L29: =G29/$F$7*100 -> 271.34982 | P29: 2002 | Q29: =AVERAGE(F29:F31) -> 405.75701 | R29: =AVERAGE(G91:G97) -> 1363.0312 | S29: =AVERAGE(H91:H97) -> 1266.5692 | T29: =(Q29-Q27)/Q27 -> 0.028571429 | U29: =(R29-R27)/R27 -> 0.11739418 | V29: =(S29-S27)/S27 -> 0.15630637
A30: s | E30: s
A31: Sep-94 | B31: 185 | C31: 412 | D31: 305 | E31: Sep-94 | F31: =B31*Sheet4!$B$28/Sheet4!$B$5 -> 417.02804 | G31: =C31*Sheet4!$B$28/Sheet4!$B$5 -> 928.73271 | H31: =D31*Sheet4!$B$28/Sheet4!$B$5 -> 687.53271 | I31: =(F31-F29)/F29 -> 0.057142857 | J31: =(G31-G29)/G29 -> 0.027431421 | K31: =F31/$F$7*100 -> 125.18632 | L31: =G31/$F$7*100 -> 278.79333 | P31: 2003 | Q31: =AVERAGE(F31:F33) -> 419.28224 | R31: =AVERAGE(G107:G113) -> 1460.8544 | S31: =AVERAGE(H107:H113) -> 1303.9557 | T31: =(Q31-Q29)/Q29 -> 0.033333333 | U31: =(R31-R29)/R29 -> 0.071768846 | V31: =(S31-S29)/S29 -> 0.029517929
A32: s | E32: s
A33: Dec-94 | B33: 187 | C33: 395 | D33: 327 | E33: Dec-94 | F33: =B33*Sheet4!$B$28/Sheet4!$B$5 -> 421.53645 | G33: =C33*Sheet4!$B$28/Sheet4!$B$5 -> 890.41121 | H33: =D33*Sheet4!$B$28/Sheet4!$B$5 -> 737.12523 | I33: =(F33-F31)/F31 -> 0.010810811 | J33: =(G33-G31)/G31 -> -0.041262136 | K33: =F33/$F$7*100 -> 126.53969 | L33: =G33/$F$7*100 -> 267.28972 | P33: 2004 | Q33: =AVERAGE(F33:F35) -> 397.24217 | R33: =AVERAGE(G107:G113) -> 1460.8544 | S33: =AVERAGE(H107:H113) -> 1303.9557 | T33: =(Q33-Q31)/Q31 -> -0.052566188 | U33: =(R33-R31)/R31 -> 0 | V33: =(S33-S31)/S31 -> 0
A34: s | E34: s
A35: Mar-95 | B35: 184 | C35: 401 | D35: 296 | E35: Mar-95 | F35: =B35*Sheet4!$B$28/Sheet4!$B$6 -> 372.9479 | G35: =C35*Sheet4!$B$28/Sheet4!$B$6 -> 812.78319 | H35: =D35*Sheet4!$B$28/Sheet4!$B$6 -> 599.95966 | I35: =(F35-F33)/F33 -> -0.11526536 | J35: =(G35-G33)/G33 -> -0.087182215 | K35: =F35/$F$7*100 -> 111.95405 | L35: =G35/$F$7*100 -> 243.98681 | P35: 2005 | Q35: =AVERAGE(F35:F37) -> 375.98824 | R35: =AVERAGE(G115:G121) -> 1405.2273 | S35: =AVERAGE(H115:H121) -> 1296 | T35: =(Q35-Q33)/Q33 -> -0.053503731 | U35: =(R35-R33)/R33 -> -0.038078508 | V35: =(S35-S33)/S33 -> -0.0061012013
A36: s | E36: s
A37: Jun-95 | B37: 187 | C37: 410 | D37: 295 | E37: Jun-95 | F37: =B37*Sheet4!$B$28/Sheet4!$B$6 -> 379.02857 | G37: =C37*Sheet4!$B$28/Sheet4!$B$6 -> 831.02521 | H37: =D37*Sheet4!$B$28/Sheet4!$B$6 -> 597.93277 | I37: =(F37-F35)/F35 -> 0.016304348 | J37: =(G37-G35)/G35 -> 0.02244389 | K37: =F37/$F$7*100 -> 113.77939 | L37: =G37/$F$7*100 -> 249.46282 | P37: 2006 | Q37: =AVERAGE(F37:F39) -> 378.01513 | R37: =AVERAGE(G123:G129) -> 1379.0833 | S37: =AVERAGE(H123:H129) -> 1284.1667 | T37: =(Q37-Q35)/Q35 -> 0.0053908356 | U37: =(R37-R35)/R35 -> -0.018604777 | V37: =(S37-S35)/S35 -> -0.0091306584
A38: s | E38: s
A39: Sep-95 | B39: 186 | C39: 413 | D39: 295 | E39: Sep-95 | F39: =B39*Sheet4!$B$28/Sheet4!$B$6 -> 377.00168 | G39: =C39*Sheet4!$B$28/Sheet4!$B$6 -> 837.10588 | H39: =D39*Sheet4!$B$28/Sheet4!$B$6 -> 597.93277 | I39: =(F39-F37)/F37 -> -0.0053475936 | J39: =(G39-G37)/G37 -> 0.0073170732 | K39: =F39/$F$7*100 -> 113.17094 | L39: =G39/$F$7*100 -> 251.28816 | P39: 2007 | Q39: =AVERAGE(F39:F41) -> 381.05546 | R39: =AVERAGE(G131:G137) -> 1403.3877 | S39: =AVERAGE(H131:H137) -> 1266.7644 | T39: =(Q39-Q37)/Q37 -> 0.0080428954 | U39: =(R39-R37)/R37 -> 0.017623549 | V39: =(S39-S37)/S37 -> -0.013551376
A40: s | E40: s
A41: Dec-95 | B41: 190 | C41: 413 | D41: 330 | E41: Dec-95 | F41: =B41*Sheet4!$B$28/Sheet4!$B$6 -> 385.10924 | G41: =C41*Sheet4!$B$28/Sheet4!$B$6 -> 837.10588 | H41: =D41*Sheet4!$B$28/Sheet4!$B$6 -> 668.87395 | I41: =(F41-F39)/F39 -> 0.021505376 | J41: =(G41-G39)/G39 -> 0 | K41: =F41/$F$7*100 -> 115.60472 | L41: =G41/$F$7*100 -> 251.28816 | P41: 2008 | Q41: =AVERAGE(F41:F43) -> 379.15071 | R41: =AVERAGE(G139:G145) -> 1295.645 | S41: =AVERAGE(H139:H145) -> 1181.1189 | T41: =(Q41-Q39)/Q39 -> -0.0049986139 | U41: =(R41-R39)/R39 -> -0.076773264 | V41: =(S41-S39)/S39 -> -0.067609657
A42: s | E42: s
A43: Mar-96 | B43: 190 | C43: 399 | D43: 300 | E43: Mar-96 | F43: =B43*Sheet4!$B$28/Sheet4!$B$7 -> 373.19218 | G43: =C43*Sheet4!$B$28/Sheet4!$B$7 -> 783.70358 | H43: =D43*Sheet4!$B$28/Sheet4!$B$7 -> 589.25081 | I43: =(F43-F41)/F41 -> -0.030944625 | J43: =(G43-G41)/G41 -> -0.06379396 | K43: =F43/$F$7*100 -> 112.02738 | L43: =G43/$F$7*100 -> 235.25749 | P43: 2009 | Q43: =AVERAGE(F43:F45) -> 381.04886 | R43: =AVERAGE(G147:G153) -> 1154.3044 | S43: =AVERAGE(H147:H153) -> 1113.3642 | T43: =(Q43-Q41)/Q41 -> 0.0050063123 | U43: =(R43-R41)/R41 -> -0.10908902 | V43: =(S43-S41)/S41 -> -0.057364858
A44: s | E44: s
A45: Jun-96 | B45: 198 | C45: 396 | D45: 312 | E45: Jun-96 | F45: =B45*Sheet4!$B$28/Sheet4!$B$7 -> 388.90554 | G45: =C45*Sheet4!$B$28/Sheet4!$B$7 -> 777.81107 | H45: =D45*Sheet4!$B$28/Sheet4!$B$7 -> 612.82085 | I45: =(F45-F43)/F43 -> 0.042105263 | J45: =(G45-G43)/G43 -> -0.007518797 | K45: =F45/$F$7*100 -> 116.74432 | L45: =G45/$F$7*100 -> 233.48864 | P45: 2010 | Q45: =AVERAGE(F45:F47) -> 390.86971 | R45: =AVERAGE(G155:G161) -> 1167.3713 | S45: =AVERAGE(H155:H161) -> 1189.9593 | T45: =(Q45-Q43)/Q43 -> 0.025773196 | U45: =(R45-R43)/R43 -> 0.011320205 | V45: =(S45-S43)/S43 -> 0.06879606
A46: s | E46: s
A47: Sep-96 | B47: 200 | C47: 420 | D47: 335 | E47: Sep-96 | F47: =B47*Sheet4!$B$28/Sheet4!$B$7 -> 392.83388 | G47: =C47*Sheet4!$B$28/Sheet4!$B$7 -> 824.95114 | H47: =D47*Sheet4!$B$28/Sheet4!$B$7 -> 657.99674 | I47: =(F47-F45)/F45 -> 0.01010101 | J47: =(G47-G45)/G45 -> 0.060606061 | K47: =F47/$F$7*100 -> 117.92356 | L47: =G47/$F$7*100 -> 247.63947 | P47: 2011 | Q47: =AVERAGE(F47:F49) -> 406.58306 | R47: =AVERAGE(G163:G169) -> 1122.2154 | S47: =AVERAGE(H163:H169) -> 1119.7237 | T47: =(Q47-Q45)/Q45 -> 0.040201005 | U47: =(R47-R45)/R45 -> -0.03868173 | V47: =(S47-S45)/S45 -> -0.059023554
...

Sheet Sheet2
A1: Non-strata Dwellings | F1: Non-strata Dwellings
A2: Area/Ring/SA | B2: Greater Sydney | C2: Ku-ring-gai | D2: Manly | F2: Area/Ring/SA | G2: Greater Sydney | H2: Ku-ring-gai | I2: Manly | K2: Greater Sydney | L2: Ku-ring-gai | M2: Manly
A3: Mar-91 | B3: 151 | C3: - | D3: - | F3: Mar-91
A5: Jun-91 | B5: 155 | C5: - | D5: 280 | F5: Jun-91
D6: s
A7: Sep-91 | B7: 160 | C7: 409 | D7: 343 | F7: Sep-91 | G7: =B7*Sheet4!$B$28/Sheet4!$B$2 -> 337.34266 | H7: =C7*Sheet4!$B$28/Sheet4!$B$2 -> 862.33217 | I7: =D7*Sheet4!$B$28/Sheet4!$B$2 -> 723.17832 | J7: 1991 | K7: =AVERAGE(G7:G9) -> 351.0472 | L7: =AVERAGE(H7:H9) -> 803.2972 | M7: =AVERAGE(I7:I9) -> 640.95105
A9: Dec-91 | B9: 173 | C9: 353 | D9: 265 | F9: Dec-91 | G9: =B9*Sheet4!$B$28/Sheet4!$B$2 -> 364.75175 | H9: =C9*Sheet4!$B$28/Sheet4!$B$2 -> 744.26224 | I9: =D9*Sheet4!$B$28/Sheet4!$B$2 -> 558.72378 | J9: 1992 | K9: =AVERAGE(G11:G17) -> 388.04167 | L9: =AVERAGE(H11:H17) -> 819.63333 | M9: =AVERAGE(I11:I17) -> 681.725
A11: Mar-92 | B11: 170 | C11: 383 | D11: 273 | F11: Mar-92 | G11: =B11*Sheet4!$B$28/Sheet4!$B$3 -> 379.66667 | H11: =C11*Sheet4!$B$28/Sheet4!$B$3 -> 855.36667 | I11: =D11*Sheet4!$B$28/Sheet4!$B$3 -> 609.7 | J11: 1993 | K11: =AVERAGE(G19:G25) -> 395.82402 | L11: =AVERAGE(H19:H25) -> 870.2514 | M11: =AVERAGE(I19:I25) -> 679.91899
A13: Jun-92 | B13: 175 | C13: 350 | D13: 295 | F13: Jun-92 | G13: =B13*Sheet4!$B$28/Sheet4!$B$3 -> 390.83333 | H13: =C13*Sheet4!$B$28/Sheet4!$B$3 -> 781.66667 | I13: =D13*Sheet4!$B$28/Sheet4!$B$3 -> 658.83333 | J13: 1994 | K13: =AVERAGE(G27:G33) -> 427.73551 | L13: =AVERAGE(H27:H33) -> 940.00374 | M13: =AVERAGE(I27:I33) -> 831.80187
A15: Sep-92 | B15: 175 | C15: 380 | D15: 323 | F15: Sep-92 | G15: =B15*Sheet4!$B$28/Sheet4!$B$3 -> 390.83333 | H15: =C15*Sheet4!$B$28/Sheet4!$B$3 -> 848.66667 | I15: =D15*Sheet4!$B$28/Sheet4!$B$3 -> 721.36667 | J15: 1995 | K15: =AVERAGE(G35:G41) -> 398.79076 | L15: =AVERAGE(H35:H41) -> 864.97563 | M15: =AVERAGE(I35:I41) -> 788.96723
A17: Dec-92 | B17: 175 | C17: 355 | D17: 330 | F17: Dec-92 | G17: =B17*Sheet4!$B$28/Sheet4!$B$3 -> 390.83333 | H17: =C17*Sheet4!$B$28/Sheet4!$B$3 -> 792.83333 | I17: =D17*Sheet4!$B$28/Sheet4!$B$3 -> 737 | J17: 1996 | K17: =AVERAGE(G43:G49) -> 414.93078 | L17: =AVERAGE(H43:H49) -> 843.11971 | M17: =AVERAGE(I43:I49) -> 815.13029
A19: Mar-93 | B19: 171 | C19: 390 | D19: 302 | F19: Mar-93 | G19: =B19*Sheet4!$B$28/Sheet4!$B$4 -> 384.03352 | H19: =C19*Sheet4!$B$28/Sheet4!$B$4 -> 875.86592 | I19: =D19*Sheet4!$B$28/Sheet4!$B$4 -> 678.23464 | J19: 1997 | K19: =AVERAGE(G51:G57) -> 495.2456 | L19: =AVERAGE(H51:H57) -> 1039.3257 | M19: =AVERAGE(I51:I57) -> 1085.5062
A20: s | F20: s
A21: Jun-93 | B21: 177 | C21: 400 | D21: 320 | F21: Jun-93 | G21: =B21*Sheet4!$B$28/Sheet4!$B$4 -> 397.50838 | H21: =C21*Sheet4!$B$28/Sheet4!$B$4 -> 898.32402 | I21: =D21*Sheet4!$B$28/Sheet4!$B$4 -> 718.65922 | J21: 1998 | K21: =AVERAGE(G59:G65) -> 530.02208 | L21: =AVERAGE(H59:H65) -> 1129.826 | M21: =AVERAGE(I59:I65) -> 1225.1767
A22: s | F22: s
A23: Sep-93 | B23: 177 | C23: 365 | D23: 279 | F23: Sep-93 | G23: =B23*Sheet4!$B$28/Sheet4!$B$4 -> 397.50838 | H23: =C23*Sheet4!$B$28/Sheet4!$B$4 -> 819.72067 | I23: =D23*Sheet4!$B$28/Sheet4!$B$4 -> 626.58101 | J23: 1999 | K23: =AVERAGE(G67:G73) -> 571.39948 | L23: =AVERAGE(H67:H73) -> 1218.951 | M23: =AVERAGE(I67:I73) -> 1378.5077
A24: s | F24: s
A25: Dec-93 | B25: 180 | C25: 395 | D25: 310 | F25: Dec-93 | G25: =B25*Sheet4!$B$28/Sheet4!$B$4 -> 404.24581 | H25: =C25*Sheet4!$B$28/Sheet4!$B$4 -> 887.09497 | I25: =D25*Sheet4!$B$28/Sheet4!$B$4 -> 696.20112 | J25: 2000 | K25: =AVERAGE(G75:G81) -> 581.32353 | L25: =AVERAGE(H75:H81) -> 1230.6324 | M25: =AVERAGE(I75:I81) -> 1426.2132
A26: s | F26: s
A27: Mar-94 | B27: 182 | C27: 396 | D27: 341 | F27: Mar-94 | G27: =B27*Sheet4!$B$28/Sheet4!$B$5 -> 410.26542 | H27: =C27*Sheet4!$B$28/Sheet4!$B$5 -> 892.66542 | I27: =D27*Sheet4!$B$28/Sheet4!$B$5 -> 768.68411 | J27: 2001 | K27: =AVERAGE(G83:G89) -> 610.83716 | L27: =AVERAGE(H83:H89) -> 1286.2156 | M27: =AVERAGE(I83:I89) -> 1470.1583
A28: s | F28: s
A29: Jun-94 | B29: 184 | C29: 417 | D29: 347 | F29: Jun-94 | G29: =B29*Sheet4!$B$28/Sheet4!$B$5 -> 414.77383 | H29: =C29*Sheet4!$B$28/Sheet4!$B$5 -> 940.00374 | I29: =D29*Sheet4!$B$28/Sheet4!$B$5 -> 782.20935 | J29: 2002 | K29: =AVERAGE(G93:G97) -> 741.1875 | L29: =AVERAGE(H93:H97) -> 1486.5625 | M29: =AVERAGE(I93:I97) -> 1752.7679
A30: s | F30: s
A31: Sep-94 | B31: 193 | C31: 435 | D31: 390 | F31: Sep-94 | G31: =B31*Sheet4!$B$28/Sheet4!$B$5 -> 435.06168 | H31: =C31*Sheet4!$B$28/Sheet4!$B$5 -> 980.57944 | I31: =D31*Sheet4!$B$28/Sheet4!$B$5 -> 879.14019 | J31: 2003 | K31: =AVERAGE(G99:G105) -> 816.98186 | L31: =AVERAGE(H99:H105) -> 1579.7025 | M31: =AVERAGE(I99:I105) -> 2019.4811
A32: s | F32: s
A33: Dec-94 | B33: 200 | C33: 420 | D33: 398 | F33: Dec-94 | G33: =B33*Sheet4!$B$28/Sheet4!$B$5 -> 450.84112 | H33: =C33*Sheet4!$B$28/Sheet4!$B$5 -> 946.76636 | I33: =D33*Sheet4!$B$28/Sheet4!$B$5 -> 897.17383 | J33: 2004 | K33: =AVERAGE(G107:G113) -> 843.01266 | L33: =AVERAGE(H107:H113) -> 1583.8291 | M33: =AVERAGE(I107:I113) -> 1918.8291
A34: s | F34: s
A35: Mar-95 | B35: 192 | C35: 427 | D35: 365 | F35: Mar-95 | G35: =B35*Sheet4!$B$28/Sheet4!$B$6 -> 389.16303 | H35: =C35*Sheet4!$B$28/Sheet4!$B$6 -> 865.48235 | I35: =D35*Sheet4!$B$28/Sheet4!$B$6 -> 739.81513 | J35: 2005 | K35: =AVERAGE(G115:G121) -> 790.36364 | L35: =AVERAGE(H115:H121) -> 1503.4091 | M35: =AVERAGE(I115:I121) -> 1784.8636
A36: s | F36: s
A37: Jun-95 | B37: 198 | C37: 420 | D37: 383 | F37: Jun-95 | G37: =B37*Sheet4!$B$28/Sheet4!$B$6 -> 401.32437 | H37: =C37*Sheet4!$B$28/Sheet4!$B$6 -> 851.29412 | I37: =D37*Sheet4!$B$28/Sheet4!$B$6 -> 776.29916 | J37: 2006 | K37: =AVERAGE(G123:G129) -> 761.72619 | L37: =AVERAGE(H123:H129) -> 1552.5655 | M37: =AVERAGE(I123:I129) -> 1904.7143
A38: s | F38: s
A39: Sep-95 | B39: 197 | C39: 430 | D39: 379 | F39: Sep-95 | G39: =B39*Sheet4!$B$28/Sheet4!$B$6 -> 399.29748 | H39: =C39*Sheet4!$B$28/Sheet4!$B$6 -> 871.56303 | I39: =D39*Sheet4!$B$28/Sheet4!$B$6 -> 768.1916 | J39: 2007 | K39: =AVERAGE(G131:G137) -> 775.23042 | L39: =AVERAGE(H131:H137) -> 1644.8973 | M39: =AVERAGE(I131:I137) -> 2044.7041
A40: s | F40: s
A41: Dec-95 | B41: 200 | C41: 430 | D41: 430 | F41: Dec-95 | G41: =B41*Sheet4!$B$28/Sheet4!$B$6 -> 405.37815 | H41: =C41*Sheet4!$B$28/Sheet4!$B$6 -> 871.56303 | I41: =D41*Sheet4!$B$28/Sheet4!$B$6 -> 871.56303 | J41: 2008 | K41: =AVERAGE(G139:G145) -> 699.96299 | L41: =AVERAGE(H139:H145) -> 1552.8714 | M41: =AVERAGE(I139:I145) -> 1967.068
A42: s | F42: s
A43: Mar-96 | B43: 200 | C43: 425 | D43: 380 | F43: Mar-96 | G43: =B43*Sheet4!$B$28/Sheet4!$B$7 -> 392.83388 | H43: =C43*Sheet4!$B$28/Sheet4!$B$7 -> 834.77199 | I43: =D43*Sheet4!$B$28/Sheet4!$B$7 -> 746.38436 | J43: 2009 | K43: =AVERAGE(G147:G153) -> 692.51323 | L43: =AVERAGE(H147:H153) -> 1536.9908 | M43: =AVERAGE(I147:I153) -> 1866.9407
A44: s | F44: s
A45: Jun-96 | B45: 210 | C45: 418 | D45: 390 | F45: Jun-96 | G45: =B45*Sheet4!$B$28/Sheet4!$B$7 -> 412.47557 | H45: =C45*Sheet4!$B$28/Sheet4!$B$7 -> 821.0228 | I45: =D45*Sheet4!$B$28/Sheet4!$B$7 -> 766.02606 | J45: 2010 | K45: =AVERAGE(G155:G161) -> 765.37134 | L45: =AVERAGE(H155:H161) -> 1590.6498 | M45: =AVERAGE(I155:I161) -> 1841.4088
A46: s | F46: s
A47: Sep-96 | B47: 212 | C47: 437 | D47: 430 | F47: Sep-96 | G47: =B47*Sheet4!$B$28/Sheet4!$B$7 -> 416.40391 | H47: =C47*Sheet4!$B$28/Sheet4!$B$7 -> 858.34202 | I47: =D47*Sheet4!$B$28/Sheet4!$B$7 -> 844.59283 | J47: 2011 | K47: =AVERAGE(G163:G169) -> 691.45661 | L47: =AVERAGE(H163:H169) -> 1463.8946 | M47: =AVERAGE(I163:I169) -> 1708.3962
...

Sheet Sheet3
A1: Strata Dwellings | F1: Strata Dwellings
A2: Area/Ring/SA | B2: Greater Sydney | C2: Ku-ring-gai | D2: Middle Ring | E2: Manly | F2: Area/Ring/SA | G2: Greater Sydney | H2: Ku-ring-gai | I2: Middle Ring | J2: Manly | P2: Greater Sydney | Q2: Ku-ring-gai | R2: Middle Ring | S2: Manly
A3: Mar-91 | B3: 135 | C3: - | D3: 162 | E3: 173 | F3: Mar-91
D4: s | E4: s
A5: Jun-91 | B5: 140 | C5: - | D5: 175 | E5: 183 | F5: Jun-91
A7: Sep-91 | B7: 137 | C7: - | D7: 135 | E7: 273 | F7: Sep-91
A9: Dec-91 | B9: 148 | C9: - | D9: 144 | E9: 169 | F9: Dec-91
A11: Mar-92 | B11: 145 | C11: 216 | D11: 137 | E11: 175 | F11: Mar-92 | G11: =B11*Sheet4!$B$28/Sheet4!$B$3 -> 323.83333 | H11: =C11*Sheet4!$B$28/Sheet4!$B$3 -> 482.4 | I11: =D11*Sheet4!$B$28/Sheet4!$B$3 -> 305.96667 | J11: =E11*Sheet4!$B$28/Sheet4!$B$3 -> 390.83333 | O11: 1992 | P11: =AVERAGE(G11:G17) -> 333.88333 | Q11: =AVERAGE(H11:H17) -> 525.39167 | R11: =AVERAGE(I11:I17) -> 317.69167 | S11: =AVERAGE(J11:J17) -> 431.03333
C12: s
A13: Jun-92 | B13: 148 | C13: 255 | D13: 138 | E13: 200 | F13: Jun-92 | G13: =B13*Sheet4!$B$28/Sheet4!$B$3 -> 330.53333 | H13: =C13*Sheet4!$B$28/Sheet4!$B$3 -> 569.5 | I13: =D13*Sheet4!$B$28/Sheet4!$B$3 -> 308.2 | J13: =E13*Sheet4!$B$28/Sheet4!$B$3 -> 446.66667 | O13: 1993 | P13: =AVERAGE(G19:G25) -> 348.10056 | Q13: =AVERAGE(H19:H25) -> 616.47486 | R13: =AVERAGE(I19:I25) -> 338.55587 | S13: =AVERAGE(J19:J25) -> 451.40782
C14: s
A15: Sep-92 | B15: 150 | C15: 225 | D15: 146 | E15: 210 | F15: Sep-92 | G15: =B15*Sheet4!$B$28/Sheet4!$B$3 -> 335 | H15: =C15*Sheet4!$B$28/Sheet4!$B$3 -> 502.5 | I15: =D15*Sheet4!$B$28/Sheet4!$B$3 -> 326.06667 | J15: =E15*Sheet4!$B$28/Sheet4!$B$3 -> 469 | O15: 1994 | P15: =AVERAGE(G27:G33) -> 371.94393 | Q15: =AVERAGE(H27:H33) -> 618.77944 | R15: =AVERAGE(I27:I33) -> 364.05421 | S15: =AVERAGE(J27:J33) -> 508.32336
C16: s
A17: Dec-92 | B17: 155 | C17: 245 | D17: 148 | E17: 187 | F17: Dec-92 | G17: =B17*Sheet4!$B$28/Sheet4!$B$3 -> 346.16667 | H17: =C17*Sheet4!$B$28/Sheet4!$B$3 -> 547.16667 | I17: =D17*Sheet4!$B$28/Sheet4!$B$3 -> 330.53333 | J17: =E17*Sheet4!$B$28/Sheet4!$B$3 -> 417.63333 | O17: 1995 | P17: =AVERAGE(G35:G41) -> 352.17227 | Q17: =AVERAGE(H35:H41) -> 545.74034 | R17: =AVERAGE(I35:I41) -> 337.98403 | S17: =AVERAGE(J35:J41) -> 475.30588
C18: s
A19: Mar-93 | B19: 154 | C19: 268 | D19: 150 | E19: 188 | F19: Mar-93 | G19: =B19*Sheet4!$B$28/Sheet4!$B$4 -> 345.85475 | H19: =C19*Sheet4!$B$28/Sheet4!$B$4 -> 601.87709 | I19: =D19*Sheet4!$B$28/Sheet4!$B$4 -> 336.87151 | J19: =E19*Sheet4!$B$28/Sheet4!$B$4 -> 422.21229 | O19: 1996 | P19: =AVERAGE(G43:G49) -> 365.82655 | Q19: =AVERAGE(H43:H49) -> 571.08225 | R19: =AVERAGE(I43:I49) -> 339.8013 | S19: =AVERAGE(J43:J49) -> 486.62296
A20: s | C20: s | F20: s
A21: Jun-93 | B21: 155 | C21: 310 | D21: 148 | E21: 220 | F21: Jun-93 | G21: =B21*Sheet4!$B$28/Sheet4!$B$4 -> 348.10056 | H21: =C21*Sheet4!$B$28/Sheet4!$B$4 -> 696.20112 | I21: =D21*Sheet4!$B$28/Sheet4!$B$4 -> 332.37989 | J21: =E21*Sheet4!$B$28/Sheet4!$B$4 -> 494.07821 | O21: 1997 | P21: =AVERAGE(G51:G57) -> 455.96567 | Q21: =AVERAGE(H51:H57) -> 743.1338 | R21: =AVERAGE(I51:I57) -> 413.50088 | S21: =AVERAGE(J51:J57) -> 666.69718
A22: s | F22: s
A23: Sep-93 | B23: 156 | C23: 265 | D23: 152 | E23: 200 | F23: Sep-93 | G23: =B23*Sheet4!$B$28/Sheet4!$B$4 -> 350.34637 | H23: =C23*Sheet4!$B$28/Sheet4!$B$4 -> 595.13966 | I23: =D23*Sheet4!$B$28/Sheet4!$B$4 -> 341.36313 | J23: =E23*Sheet4!$B$28/Sheet4!$B$4 -> 449.16201 | O23: 1998 | P23: =AVERAGE(G59:G65) -> 493.79947 | Q23: =AVERAGE(H59:H65) -> 714.33127 | R23: =AVERAGE(I59:I65) -> 465.03445 | S23: =AVERAGE(J59:J65) -> 735.63869
A24: s | F24: s
A25: Dec-93 | B25: 155 | C25: 255 | D25: 153 | E25: 196 | F25: Dec-93 | G25: =B25*Sheet4!$B$28/Sheet4!$B$4 -> 348.10056 | H25: =C25*Sheet4!$B$28/Sheet4!$B$4 -> 572.68156 | I25: =D25*Sheet4!$B$28/Sheet4!$B$4 -> 343.60894 | J25: =E25*Sheet4!$B$28/Sheet4!$B$4 -> 440.17877 | O25: 1999 | P25: =AVERAGE(G67:G73) -> 528.9201 | Q25: =AVERAGE(H67:H73) -> 735.61856 | R25: =AVERAGE(I67:I73) -> 501.46392 | S25: =AVERAGE(J67:J73) -> 776.54381
A26: s | F26: s
A27: Mar-94 | B27: 158 | C27: 253 | D27: 155 | E27: 206 | F27: Mar-94 | G27: =B27*Sheet4!$B$28/Sheet4!$B$5 -> 356.16449 | H27: =C27*Sheet4!$B$28/Sheet4!$B$5 -> 570.31402 | I27: =D27*Sheet4!$B$28/Sheet4!$B$5 -> 349.40187 | J27: =E27*Sheet4!$B$28/Sheet4!$B$5 -> 464.36636 | O27: 2000 | P27: =AVERAGE(G75:G81) -> 538.95588 | Q27: =AVERAGE(H75:H81) -> 779.36765 | R27: =AVERAGE(I75:I81) -> 508.41176 | S27: =AVERAGE(J75:J81) -> 837.5
A28: s | F28: s
A29: Jun-94 | B29: 159 | C29: 291 | D29: 157 | E29: 231 | F29: Jun-94 | G29: =B29*Sheet4!$B$28/Sheet4!$B$5 -> 358.41869 | H29: =C29*Sheet4!$B$28/Sheet4!$B$5 -> 655.97383 | I29: =D29*Sheet4!$B$28/Sheet4!$B$5 -> 353.91028 | J29: =E29*Sheet4!$B$28/Sheet4!$B$5 -> 520.7215 | O29: 2001 | P29: =AVERAGE(G83:G89) -> 570.72936 | Q29: =AVERAGE(H83:H89) -> 768.9633 | R29: =AVERAGE(I83:I89) -> 535.69266 | S29: =AVERAGE(J83:J89) -> 859.78211
A30: s | F30: s
A31: Sep-94 | B31: 170 | C31: 286 | D31: 164 | E31: 220 | F31: Sep-94 | G31: =B31*Sheet4!$B$28/Sheet4!$B$5 -> 383.21495 | H31: =C31*Sheet4!$B$28/Sheet4!$B$5 -> 644.7028 | I31: =D31*Sheet4!$B$28/Sheet4!$B$5 -> 369.68972 | J31: =E31*Sheet4!$B$28/Sheet4!$B$5 -> 495.92523 | O31: 2002 | P31: =AVERAGE(G91:G97) -> 635.30357 | Q31: =AVERAGE(H91:H97) -> 837.64955 | R31: =AVERAGE(I91:I97) -> 601.65402 | S31: =AVERAGE(J91:J97) -> 977.6317
A32: s | F32: s
A33: Dec-94 | B33: 173 | C33: 268 | D33: 170 | E33: 245 | F33: Dec-94 | G33: =B33*Sheet4!$B$28/Sheet4!$B$5 -> 389.97757 | H33: =C33*Sheet4!$B$28/Sheet4!$B$5 -> 604.1271 | I33: =D33*Sheet4!$B$28/Sheet4!$B$5 -> 383.21495 | J33: =E33*Sheet4!$B$28/Sheet4!$B$5 -> 552.28037 | O33: 2003 | P33: =AVERAGE(G99:G105) -> 662.07475 | Q33: =AVERAGE(H99:H105) -> 934.69376 | R33: =AVERAGE(I99:I105) -> 638.88244 | S33: =AVERAGE(J99:J105) -> 1067.2837
A34: s | F34: s
A35: Mar-95 | B35: 172 | C35: 250 | D35: 168 | E35: 223 | F35: Mar-95 | G35: =B35*Sheet4!$B$28/Sheet4!$B$6 -> 348.62521 | H35: =C35*Sheet4!$B$28/Sheet4!$B$6 -> 506.72269 | I35: =D35*Sheet4!$B$28/Sheet4!$B$6 -> 340.51765 | J35: =E35*Sheet4!$B$28/Sheet4!$B$6 -> 451.99664 | O35: 2004 | P35: =AVERAGE(G107:G113) -> 653.88608 | Q35: =AVERAGE(H107:H113) -> 851.06962 | R35: =AVERAGE(I107:I113) -> 622.93038 | S35: =AVERAGE(J107:J113) -> 979.55696
A36: s | F36: s
A37: Jun-95 | B37: 173 | C37: 277 | D37: 165 | E37: 233 | F37: Jun-95 | G37: =B37*Sheet4!$B$28/Sheet4!$B$6 -> 350.6521 | H37: =C37*Sheet4!$B$28/Sheet4!$B$6 -> 561.44874 | I37: =D37*Sheet4!$B$28/Sheet4!$B$6 -> 334.43697 | J37: =E37*Sheet4!$B$28/Sheet4!$B$6 -> 472.26555 | O37: 2005 | P37: =AVERAGE(G115:G121) -> 636.13636 | Q37: =AVERAGE(H115:H121) -> 920.86364 | R37: =AVERAGE(I115:I121) -> 602.59091 | S37: =AVERAGE(J115:J121) -> 985.90909
A38: s | F38: s
A39: Sep-95 | B39: 173 | C39: 250 | D39: 165 | E39: 232 | F39: Sep-95 | G39: =B39*Sheet4!$B$28/Sheet4!$B$6 -> 350.6521 | H39: =C39*Sheet4!$B$28/Sheet4!$B$6 -> 506.72269 | I39: =D39*Sheet4!$B$28/Sheet4!$B$6 -> 334.43697 | J39: =E39*Sheet4!$B$28/Sheet4!$B$6 -> 470.23866 | O39: 2006 | P39: =AVERAGE(G123:G129) -> 617.75595 | Q39: =AVERAGE(H123:H129) -> 876.98214 | R39: =AVERAGE(I123:I129) -> 581.8631 | S39: =AVERAGE(J123:J129) -> 955.54762
A40: s | F40: s
A41: Dec-95 | B41: 177 | C41: 300 | D41: 169 | E41: 250 | F41: Dec-95 | G41: =B41*Sheet4!$B$28/Sheet4!$B$6 -> 358.75966 | H41: =C41*Sheet4!$B$28/Sheet4!$B$6 -> 608.06723 | I41: =D41*Sheet4!$B$28/Sheet4!$B$6 -> 342.54454 | J41: =E41*Sheet4!$B$28/Sheet4!$B$6 -> 506.72269 | O41: 2007 | P41: =AVERAGE(G131:G137) -> 617.32028 | Q41: =AVERAGE(H131:H137) -> 877.40757 | R41: =AVERAGE(I131:I137) -> 581.32606 | S41: =AVERAGE(J131:J137) -> 957.91078
A42: s | F42: s
A43: Mar-96 | B43: 179 | C43: 280 | D43: 169 | E43: 247 | F43: Mar-96 | G43: =B43*Sheet4!$B$28/Sheet4!$B$7 -> 351.58632 | H43: =C43*Sheet4!$B$28/Sheet4!$B$7 -> 549.96743 | I43: =D43*Sheet4!$B$28/Sheet4!$B$7 -> 331.94463 | J43: =E43*Sheet4!$B$28/Sheet4!$B$7 -> 485.14984 | O43: 2008 | P43: =AVERAGE(G139:G145) -> 568.60558 | Q43: =AVERAGE(H139:H145) -> 890.59587 | R43: =AVERAGE(I139:I145) -> 546.2858 | S43: =AVERAGE(J139:J145) -> 878.15534
...

Sheet Sheet4
A1: Housing CPI | E1: Greater Metropolitan Region (GMR) | F1: Greater Sydney | G1: Rings | H1: Local Government Area (LGA) | I1: DwellingType | J1: First Quartile Sales Price $'000s | K1: Median Sales Price $'000s | L1: Third Quartile Sales Price '000s | M1: Mean Sales Price $'000s | N1: Sales No. | O1: Qtly change in Median | P1: Annual change in Median | Q1: Qtly change in Count | R1: Annual change in Count
A2: 33390 | B2: 57.2 | E2: Total | F2: Total | G2: Total | H2: Ku-Ring-Gai | I2: Total | J2: 1200 | K2: 2284 | L2: 3124 | M2: 2372 | N2: 670 | O2: -0.007 | P2: 0.2689 | Q2: 0.2384 | R2: 0.882 | S2: Ku-ring-gai | T2: 2017 | U2: 2021
A3: 33756 | B3: 54 | E3: Total | F3: Total | G3: Total | H3: Ku-Ring-Gai | I3: Non Strata | J3: 2472 | K3: 2928 | L3: 3724 | M3: 3179 | N3: 398 | O3: 0.0363 | P3: 0.3069 | Q3: 0.1404 | R3: 0.6515 | S3: All dwellings | T3: =AVERAGE(Sheet1!G211) -> 1868 | U3: =K5 -> 2226.7615 | V3: =(U3-T3)/T3 -> 0.19205649
A4: 34121 | B4: 53.7 | E4: Total | F4: Total | G4: Total | H4: Ku-Ring-Gai | I4: Strata | J4: 872 | K4: 1060 | L4: 1417 | M4: 1191 | N4: 272 | O4: 0.0707 | P4: 0.1623 | Q4: 0.4167 | R4: 1.3652 | S4: Non-strata | T4: =Sheet2!L59 -> 2275 | U4: =K6 -> 2854.6225 | V4: =(U4-T4)/T4 -> 0.25477911
A5: 34486 | B5: 53.5 | J5: =J2*$B$28/$B$32 -> 1169.9272 | K5: =K2*$B$28/$B$32 -> 2226.7615 | L5: =L2*$B$28/$B$32 -> 3045.7106 | M5: =M2*$B$28/$B$32 -> 2312.5562 | S5: Strata | T5: =Sheet3!Q61 -> 930 | U5: =K7 -> 1033.4357 | V5: =(U5-T5)/T5 -> 0.11122122
A6: 34851 | B6: 59.5 | J6: =J3*$B$28/$B$32 -> 2410.0501 | K6: =K3*$B$28/$B$32 -> 2854.6225 | L6: =L3*$B$28/$B$32 -> 3630.6742 | M6: =M3*$B$28/$B$32 -> 3099.3323
A7: 35217 | B7: 61.4 | D7: Ku-ring-gai | J7: =J4*$B$28/$B$32 -> 850.14713 | K7: =K4*$B$28/$B$32 -> 1033.4357 | L7: =L4*$B$28/$B$32 -> 1381.4891 | M7: =M4*$B$28/$B$32 -> 1161.1528 | T7: Ku-ring-gai | U7: Greater Sydney
A8: 35582 | B8: 56.8 | C8: Non-strata | D8: =(Sheet2!L59-Sheet2!L7)/Sheet2!L7 -> 1.8320776 | T8: =K5 -> 2226.7615 | U8: =L29 -> 935.94179
A9: 35947 | B9: 56.6 | C9: Strata | D9: =(Sheet3!Q61-Sheet3!Q11)/Sheet3!Q11 -> 0.77010801 | T9: =K6 -> 2854.6225 | U9: =L30 -> 1228.4236
A10: 36312 | B10: 58.2 | T10: =K7 -> 1033.4357 | U10: =L31 -> 760.45271
A11: 36678 | B11: 61.2
A12: 37043 | B12: 65.4
A13: 37408 | B13: 67.2
A14: 37773 | B14: 68.9
A15: 38139 | B15: 71.1
A16: 38504 | B16: 73.7
A17: 38869 | B17: 75.6 | E17: Total | F17: Total | G17: Total | H17: Northern Beaches | I17: Total | J17: 1225 | K17: 2075 | L17: 2710 | M17: 2165 | N17: 1355 | O17: 0.1156 | P17: 0.3387 | Q17: 0.1732 | R17: 0.5486 | S17: Manly | T17: 2017 | U17: 2021
A18: 39234 | B18: 77.9 | E18: Total | F18: Total | G18: Total | H18: Northern Beaches | I18: Non Strata | J18: 2225 | K18: 2610 | L18: 3435 | M18: 2942 | N18: 725 | O18: 0.0832 | P18: 0.3737 | Q18: 0.2164 | R18: 0.4646 | S18: All dwellings | T18: =Sheet1!S59 -> 1838 | U18: =Sheet4!K20 -> 2022.9992 | V18: =(U18-T18)/T18 -> 0.10065244
A19: 39600 | B19: 82.4 | E19: Total | F19: Total | G19: Total | H19: Northern Beaches | I19: Strata | J19: 881 | K19: 1188 | L19: 1530 | M19: 1270 | N19: 630 | O19: 0.115 | P19: 0.2908 | Q19: 0.127 | R19: 0.6579 | S19: Non-strata | T19: =Sheet2!M59 -> 2678 | U19: =K21 -> 2544.5918 | V19: =(U19-T19)/T19 -> -0.049816373
A20: 39965 | B20: 86.9 | J20: =J17*$B$28/$B$32 -> 1194.3007 | K20: =K17*$B$28/$B$32 -> 2022.9992 | L20: =L17*$B$28/$B$32 -> 2642.0857 | M20: =M17*$B$28/$B$32 -> 2110.7437 | S20: Strata | T20: =Sheet3!S61 -> 1364 | U20: =K22 -> 1158.228 | V20: =(U20-T20)/T20 -> -0.15085926
A21: 40330 | B21: 92.1 | J21: =J18*$B$28/$B$32 -> 2169.2401 | K21: =K18*$B$28/$B$32 -> 2544.5918 | L21: =L18*$B$28/$B$32 -> 3348.9167 | M21: =M18*$B$28/$B$32 -> 2868.2716
A22: 40695 | B22: 96.8 | J22: =J19*$B$28/$B$32 -> 858.92158 | K22: =K19*$B$28/$B$32 -> 1158.228 | L22: =L19*$B$28/$B$32 -> 1491.6572 | M22: =M19*$B$28/$B$32 -> 1238.173
A23: 41061 | B23: 101
A24: 41426 | B24: 106.6
A25: 41791 | B25: 110.8
A26: 42156 | B26: 114.9 | F26: Total | G26: Greater Sydney | H26: Total | I26: Total | J26: Total | K26: 723 | L26: 960 | M26: 1530 | N26: 1303 | O26: 26297 | P26: 0.0667 | Q26: 0.1098 | R26: 0.1357 | S26: 0.9027 | T26: Greater Sydney | U26: 2017 | V26: 2021
A27: 42522 | B27: 116.7 | F27: Total | G27: Greater Sydney | H27: Total | I27: Total | J27: Non Strata | K27: 860 | L27: 1260 | M27: 1930 | N27: 1610 | O27: 13997 | P27: 0.0957 | Q27: 0.26 | R27: 0.1313 | S27: 0.6931 | T27: All dwellings | U27: =Sheet1!Q59 -> 503.92049 | V27: =Sheet4!K29 -> 704.88116 | W27: =(V27-U27)/U27 -> 0.3987944
A28: 42887 | B28: 120.6 | F28: Total | G28: Greater Sydney | H28: Total | I28: Total | J28: Strata | K28: 618 | L28: 780 | M28: 1085 | N28: 954 | O28: 12300 | P28: 0.04 | Q28: 0.047 | R28: 0.1408 | S28: 1.2146 | T28: Non-strata | U28: =Sheet2!K59 -> 900 | V28: =Sheet4!K30 -> 838.44786 | W28: =(V28-U28)/U28 -> -0.068391269
A29: 43252 | B29: 125.1 | K29: =K26*$B$28/$B$32 -> 704.88116 | L29: =L26*$B$28/$B$32 -> 935.94179 | M29: =M26*$B$28/$B$32 -> 1491.6572 | N29: =N26*$B$28/$B$32 -> 1270.346 | T29: Strata | U29: =Sheet3!P61 -> 720 | V29: =Sheet4!K31 -> 602.51253 | W29: =(V29-U29)/U29 -> -0.16317704
A30: 43617 | B30: 126.4 | K30: =K27*$B$28/$B$32 -> 838.44786 | L30: =L27*$B$28/$B$32 -> 1228.4236 | M30: =M27*$B$28/$B$32 -> 1881.633 | N30: =N27*$B$28/$B$32 -> 1569.6524
A31: 43983 | B31: 124.8 | K31: =K28*$B$28/$B$32 -> 602.51253 | L31: =L28*$B$28/$B$32 -> 760.45271 | M31: =M28*$B$28/$B$32 -> 1057.8092 | N31: =N28*$B$28/$B$32 -> 930.09216
A32: 44348 | B32: 123.7

Sheet Advantage

Sheet Disadvantage

Sheet Recommendation

Sheet Reflection
